Workbook

Sheet PORTADA
Z1: DISEÑO DE INGENIERÍA | BC1: CODIGO: | BO1: P2437-HV-CAL-001 | CB1: REVIZADO | CC1: JULIO 23 DEL 2026
BC2: REVISION: | BO2: CERO (0) | CB2: APROBADO | CC2: JULIO 24 DEL 2026
Z3: SISTEMA HVAC LABORATORIO BRINSA | BC3: FECHA: | BO3: JULIO 23 DEL 2026
BC4: ELABORO: | BO4: J.ARBOLEDA
Z5: MEMORIA DE CÁLCULO DEL SISTEMA DE VENTILACIÓN Y PRESURIZACIÓN DEL LABORATORIO | BC5: REVISO: | BO5: F.NAVIA
A6: PROYECTO | N6: P2437 | BC6: APROBO: | BO6: H.ROSERO
R21: Elaborado por: | AF21: Revisado por: | AT21: Aprobado por:
R24: J.ARBOLEDA
R27: ="Fecha :"&BO3 -> Fecha :JULIO 23 DEL 2026 | AF27: ="Fecha :"&CC1 -> Fecha :JULIO 23 DEL 2026 | AT27: ="Fecha :"&CC2 -> Fecha :JULIO 24 DEL 2026
O39: Versión | V39: Autor | AC39: Descripción | AP39: Fecha de elaboración | AW39: Fecha de revisión | BD39: Revisado por
O42: CERO (0) | V42: J.ARBOLEDA | AC42: Emitido para cotizacion | AP42: =BO3 -> JULIO 23 DEL 2026 | AW42: =AT27 -> Fecha :JULIO 24 DEL 2026 | BD42: =BO5 -> F.NAVIA

Sheet MEMORIA DE CÁLCULO
C1: =PORTADA!Z1 -> DISEÑO DE INGENIERÍA | D1: CODIGO: | E1: =PORTADA!BO1 -> P2437-HV-CAL-001
C2: =PORTADA!Z3 -> SISTEMA HVAC LABORATORIO BRINSA | D2: REVISION: | E2: =PORTADA!BO2 -> CERO (0)
D3: FECHA: | E3: =PORTADA!BO3 -> JULIO 23 DEL 2026
C4: =PORTADA!Z5 -> MEMORIA DE CÁLCULO DEL SISTEMA DE VENTILACIÓN Y PRESURIZACIÓN DEL LABORATORIO | D4: ELABORO: | E4: =PORTADA!BO4 -> J.ARBOLEDA
D5: REVISO: | E5: =PORTADA!BO5 -> F.NAVIA
A6: PROYECTO: | B6: =PORTADA!N6 -> P2437 | D6: APROBO: | E6: =PORTADA!BO6 -> H.ROSERO
A7: 1 | B7: 2 | C7: 3 | D7: 4 | E7: 5 | F7: 6
A9: 1. DATOS GENERALES — MEMORIA DE CÁLCULO, SISTEMA DE VENTILACIÓN Y PRESURIZACIÓN
A11: Información del proyecto
A12: Concepto | B12: Valor | C12: Unidad | D12: Observación
A13: Nombre del proyecto | B13: Laboratorio Brinsa | C13: - | D13: Ventilación por impulsión con presión positiva
A14: Ubicación | B14: C:\Users\ingen\OneDrive\Escritorio\HVAC\Calculos | C14: - | D14: Carpeta de cálculos del proyecto
A15: Volumen efectivo del laboratorio (V) | B15: 320 | C15: m³ | D15: Medición / modelo 3D
A16: Renovaciones de aire (N) | B16: 12 | C16: ren/h | D16: Sustentado normativamente
A17: Objetivo | B17: Presurización positiva | C17: - | D17: Evitar ingreso de contaminantes
A18: Estrategia | B18: Ventilador directo + rejillas de exfiltración | C18: - | D18: Sin ductos de impulsión
A20: Objetivo del documento
A21: Presentar de forma atómica, funcional y verificable el cálculo del caudal de aire, potencia del ventilador, área de impulsión del ventilador (sin ductos), área/dimensiones de las rejillas de exfiltración para modelado CFD, y el cierre presión–caudal que sustenta la presurización, con sustentación normativa.
A25: 2. PARÁMETROS DE ENTRADA
A27: Parámetro | B27: Símbolo | C27: Valor | D27: Unidad | E27: Referencia / Nota
A28: Volumen efectivo del laboratorio | B28: V | C28: 320 | D28: m³ | E28: Medición directa o del modelo
A29: Renovaciones de aire | B29: N | C29: 12 | D29: ren/h | E29: Ver sección 5. NORMATIVA
A30: Presión total estimada del ventilador | B30: ΔP | C30: 190 | D30: Pa | E30: Escenario MERV cargado (ver sección 6. ESCENARIOS DE FILTRACIÓN)
A31: Eficiencia total del ventilador | B31: η | C31: 0.6 | D31: - | E31: Centrífugo/axial típico
A32: Velocidad en boca del ventilador | B32: v_vent | C32: 8 | D32: m/s | E32: Para CFD, rango 6–12 m/s
A33: Velocidad de exfiltración en rejillas | B33: v_sal | C33: 3 | D33: m/s | E33: Rango recomendado 2.5–4.0 m/s
A34: Número de rejillas de salida | B34: n_rej | C34: 3 | D34: unid. | E34: Distribución propuesta
A35: Proporción ancho/alto rejilla | B35: prop | C35: 0.95 | D35: - | E35: 353 mm × 336 mm ≈ 0.95
A36: Densidad del aire | B36: rho | C36: 0.88 | D36: kg/m³ | E36: Bases de diseño (Cajicá, 2 558 msnm, P_atm = 74.1 kPa, aire 20 °C)
A37: Coeficiente de descarga orificio | B37: Cd | C37: 0.6 | D37: - | E37: Orificio borde afilado, ASHRAE Handbook Fundamentals
A38: Set-point presión diferencial | B38: ΔP_pos | C38: 25 | D38: Pa | E38: Presión positiva vs zona adyacente
A40: Notas:
A41: • Modifique los valores en amarillo; todos los cálculos se actualizan automáticamente.
A42: • Las fórmulas están visibles en la barra de fórmulas de cada celda.
A43: • Unidades: 1 m³/min = 35.3147 CFM; 1 kW = 1.341 HP.
A45: 3. DESARROLLO DE CÁLCULOS
A47: Paso | B47: Descripción | C47: Fórmula / Valor | D47: Resultado | E47: Unidad | F47: Referencia celda
A48: 1 | B48: Caudal de aire volumétrico | C48: Q = V × N / 60 | D48: =C28*C29/60 -> 64 | E48: m³/min | F48: =D48 -> 64
A49: 2 | B49: Caudal de aire en m³/h | C49: Q_h = Q × 60 | D49: =D48*60 -> 3840 | E49: m³/h | F49: =D49 -> 3840
A50: 3 | B50: Caudal de aire en CFM | C50: Q_cfm = Q × 35.3147 | D50: =D48*35.3147 -> 2260.1408 | E50: CFM | F50: =D50 -> 2260.1408
...
